<mujoco>
  <visual>
    <global offwidth="640" offheight="640"/>
  </visual>
  <option gravity="0 0 -9.81"/>
  <asset>
		<mesh name="body" file="mesh/mujoco_simplified_body.stl"/>
    <mesh name="wheel" file="mesh/actuator_rotor_simplified.stl"/>
	</asset>
  <worldbody>
    <light diffuse=".9 .9 .9" pos="0 0 5" dir="0 0 -1"/>
    <geom name="ground" type="plane" size="5 5 0.1" rgba=".9 .9 .9 1"/>
    <body name ="body" pos="0 0 .0645" euler="0 0 0">
      <inertial pos="0 0 0" mass="0.400" diaginertia="220e-6 190e-6 300e-6"/> 
      <site name = "imu_1" pos = "-0.0234 -0.0204 0.01939" euler="180 0 90" type="box" size="0.0045 0.003 0.00095"/>
      <site name = "imu_2" pos = "0.0234 0.0204 0.01939" euler="180 0 90" type="box" size="0.0045 0.003 0.00095"/>
      <site name = "imu_3" pos = "-0.016427 0.020172 -0.01889" euler="0 0 90" type="box" size="0.0045 0.003 0.00095"/>
      <site name = "imu_4" pos = "0.016368 -0.020481 -0.018916" euler="0 0 90" type="box" size="0.0045 0.003 0.00095"/>
      <joint type="free"/>
      <geom name="body_geom" type="mesh" mesh="body"/>
      <body name ="wheel1" pos="0 0 -0.0325" euler="0 0 -90">
        <inertial pos="0 0 0" mass="0.129" diaginertia="100e-6 53e-6 53e-6"/> 
        <joint name="w1" type="hinge" pos="0 0 0" axis="-1 0 0" damping="0.001"/>
        <geom name="wheel_1_geom" type="mesh" mesh="wheel"/>
      </body>
      <body name ="wheel2" pos="0 0 0.0325" euler="0 0 0">
        <inertial pos="0 0 0" mass="0.129" diaginertia="100e-6 53e-6 53e-6"/> 
        <joint name="w2" type="hinge" pos="0 0 0" axis="1 0 0" damping="0.0001"/>
        <geom name="wheel_2_geom" type="mesh" mesh="wheel"/>
      </body>
    </body>
    <!-- Overhead Camera-->
    <camera name="overhead" pos="0 0 3" quat="1 0 0 0" mode="fixed"/>
    <camera name="balancing_view" pos="0.000 -0.545 0.545" xyaxes="1.000 -0.000 0.000 0.000 0.707 0.707" mode="fixed"/>

    <!-- Wall 1: North -->
    <geom name="wall_north" type="box" pos="0 1 0.25" size="1.05 0.05 0.25" rgba="0 0 1 1" friction="1 0.1 0.1"/>
    <!-- Wall 2: South -->
    <geom name="wall_south" type="box" pos="0 -1 0.25" size="1.05 0.05 0.25" rgba="0 1 0 1" friction="1 0.1 0.1"/>
    <!-- Wall 3: East -->
    <geom name="wall_east" type="box" pos="1 0 0.25" size="0.05 0.95 0.25" rgba="1 0 0 1" friction="1 0.1 0.1"/>
    <!-- Wall 4: West -->
    <geom name="wall_west" type="box" pos="-1 0 0.25" size="0.05 0.95 0.25" rgba="0 0 0 1" friction="1 0.1 0.1"/>
  </worldbody>
  <actuator>
    <motor name="motor_1" joint="w1" gear="1" ctrlrange="-0.5 0.5"/>
    <motor name="motor_2" joint="w2" gear="1" ctrlrange="-0.5 0.5"/>
  </actuator>
  <sensor>
    <accelerometer name="acc_1" site="imu_1"/>
    <accelerometer name="acc_2" site="imu_2"/>
    <accelerometer name="acc_3" site="imu_3"/>
    <accelerometer name="acc_4" site="imu_4"/>

    <gyro name="gyr_1" site="imu_1"/>
    <gyro name="gyr_2" site="imu_2"/>
    <gyro name="gyr_3" site="imu_3"/>
    <gyro name="gyr_4" site="imu_4"/>

    <actuatorpos name="motor_1_pos" actuator="motor_1"/>
    <actuatorpos name="motor_2_pos" actuator="motor_2"/>
  </sensor>
  <contact>
    <exclude body1="wheel1" body2="wheel2"/>
    <exclude body1="wheel1" body2="body"/>
    <exclude body1="wheel2" body2="body"/>

    <pair geom1="wheel_1_geom" geom2="ground" condim="6" friction="1 1 0.005 0.0001 0.0001" solimp="0.9 0.95 0.001 0.5 2" solref="0.02 1"/>
  </contact>
</mujoco>
